Workbook

Sheet Comparatif
A1: Revenu disponible mensuel – comparatif Mme GRAMOND / M. DU VIVIER (RG 26/35379, audience du 30/10/2026)
A2: Sources : requête Mme GRAMOND notifiée le 03/06/2026 (col. B) ; conclusions Mme GRAMOND VF du 27/10/2026 (col. C) ; projet de conclusions en réplique M. DU VIVIER au 18/09/2026 (col. E). Montants mensuels en euros, tels que déclarés par chaque partie.
A4: Poste | B4: Mme GRAMOND requête juin 2026 | C4: Mme GRAMOND conclusions oct. 2026 | D4: Pièce Mme | E4: M. DU VIVIER projet 18/09/2026 | F4: Pièce M. | G4: Écart Mme (oct.) – M.
A5: RESSOURCES MENSUELLES
A6: Salaires nets (chiffre retenu par la partie) | B6: 7049.75 | C6: 7029.4 | D6: 33 / 68-69 | E6: =130116/12 -> 10843 | F6: 26 | G6: =C6-E6 -> -3813.6
A7: Revenus fonciers nets | B7: 0 | C7: 0 | D7: 68 | E7: =1657/12 -> 138.08333 | F7: 26 | G7: =C7-E7 -> -138.08333
A8: Pension alimentaire perçue (2 500 €/mois, non intégrée par Mme) | B8: 0 | C8: 0 | D8: Jugement 09/05/2023 | G8: =C8-E8 -> 0
A9: Total ressources | B9: =SUM(B6:B8) -> 7049.75 | C9: =SUM(C6:C8) -> 7029.4 | E9: =SUM(E6:E8) -> 10981.083 | G9: =C9-E9 -> -3951.6833
A10: CHARGES DE LOGEMENT
A11: Crédit immobilier (résidence principale) | B11: 2455.69 | C11: 2455.69 | D11: 34 | G11: =C11-E11 -> 2455.69
A12: Assurance emprunt immobilier | B12: 93.84 | C12: 93.84 | D12: 35 | G12: =C12-E12 -> 93.84
A13: Charges de copropriété / charges locatives | B13: 340.3 | C13: 340.3 | D13: 36 | E13: 723 | F13: 32 | G13: =C13-E13 -> -382.7
A14: Taxe foncière | B14: 191.83 | C14: 191.83 | D14: 37 | G14: =C14-E14 -> 191.83
A15: Électricité | B15: 64.05 | C15: 64.05 | D15: 38 | E15: 217.16 | F15: 30 | G15: =C15-E15 -> -153.11
A16: Assurance habitation | B16: 46.13 | C16: 46.13 | D16: 39 | E16: 0 | F16: (à produire) | G16: =C16-E16 -> 46.13
A17: Internet / téléphonie | B17: 126.24 | C17: 126.24 | D17: 42 | E17: 100.98 | F17: 31 | G17: =C17-E17 -> 25.26
A18: Parking | E18: 198 | F18: 33 | G18: =C18-E18 -> -198
A19: Sous-total logement | B19: =SUM(B11:B18) -> 3318.08 | C19: =SUM(C11:C18) -> 3318.08 | E19: =SUM(E11:E18) -> 1239.14 | G19: =C19-E19 -> 2078.94
A20: CHARGES PERSONNELLES
A21: Impôt sur le revenu | B21: 390.75 | C21: 1251.33 | D21: 33 / 68 | E21: =16694/12 -> 1391.1667 | F21: 26 | G21: =C21-E21 -> -139.83667
A22: Assurance garantie accidents de la vie | B22: 13.21 | C22: 13.21 | D22: 40 | G22: =C22-E22 -> 13.21
A23: Assurance protection juridique | B23: 9.9 | C23: 9.9 | D23: 41 | G23: =C23-E23 -> 9.9
A24: Prêt étudiant HEC | B24: 845.68 | C24: 845.68 | D24: 43 | G24: =C24-E24 -> 845.68
A25: Prêt travaux | B25: 141.34 | C25: 141.34 | D25: 44 | G25: =C25-E25 -> 141.34
A26: Crédit à la consommation | C26: 400 | D26: 70 | G26: =C26-E26 -> 400
A27: Complémentaire santé | C27: 91.2 | D27: 79 | G27: =C27-E27 -> 91.2
A28: Surcomplémentaire santé | C28: 153.42 | D28: 80 | G28: =C28-E28 -> 153.42
A29: Sous-total charges personnelles | B29: =SUM(B21:B28) -> 1400.88 | C29: =SUM(C21:C28) -> 2906.08 | E29: =SUM(E21:E28) -> 1391.1667 | G29: =C29-E29 -> 1514.9133
A30: CHARGES LIÉES À ALIÉNOR
A31: Pension alimentaire versée | E31: 2570 | F31: Jugement 09/05/2023 | G31: =C31-E31 -> -2570
A32: Frais de scolarité | E32: =3663/12 -> 305.25 | F32: 34 | G32: =C32-E32 -> -305.25
A33: Centre aéré / centre de loisirs | B33: 62.53 | C33: 62.53 | D33: 45 | G33: =C33-E33 -> 62.53
A34: Frais de garde (CESU / nounou / baby-sitting) | B34: 907 | C34: 907 | D34: 33 et 46 | E34: =14923.67/12 -> 1243.6392 | F34: 35 | G34: =C34-E34 -> -336.63917
A35: Jeune fille au pair – argent de poche / salaire | E35: 649.5 | F35: (à produire) | G35: =C35-E35 -> -649.5
A36: Jeune fille au pair – charges sociales | E36: 232.33 | F36: (à produire) | G36: =C36-E36 -> -232.33
A37: Psychologue (suivi bimensuel) | B37: 140 | C37: 140 | D37: 18, 47, 56 | G37: =C37-E37 -> 140
A38: Piscine (moitié chacun) | B38: 15.41 | C38: 15.41 | D38: 48 | E38: 15.41 | F38: adv. 48 | G38: =C38-E38 -> 0
A39: Gym (moitié chacun) | B39: 35.58 | C39: 35.58 | D39: 49 | E39: 34.58 | F39: adv. 49 | G39: =C39-E39 -> 1
A40: Navigo | B40: 2.06 | C40: 2.06 | D40: 50 | G40: =C40-E40 -> 2.06
A41: Assurance scolaire et civile | B41: 1.49 | C41: 1.49 | D41: 51 | G41: =C41-E41 -> 1.49
...

Sheet Corrections
A1: Scénarios corrigés – leviers à ajuster (cellules jaunes)
A2: Chaque bloc part du disponible calculé dans l'onglet Comparatif, puis applique des retraitements. Les cellules jaunes sont des hypothèses à ajuster ; mettre 0 ou 0 % pour neutraliser un retraitement.
A4: Retraitement | B4: Hypothèse | C4: Effet mensuel (€) | D4: Justification / écart Mme – M. (synthèse)
A5: MME GRAMOND – à partir des conclusions d'octobre 2026
A6: Disponible calculé (onglet Comparatif, col. C) | B6: =Comparatif!C45 -> -358.83 | D6: Lien vers l'onglet Comparatif.
A7: Réintégrer la pension alimentaire perçue | B7: 2500 | C7: =B7 -> 2500 | D7: Le jugement du 09/05/2023 fixe 2 500 €/mois (2 570 € indexés selon le projet de M.). Mme l'omet de ses ressources.
A8: Retenir le revenu 2025 plutôt que la moyenne 2026 (écart mensuel) | B8: =88664/12-7029.4 -> 359.26667 | C8: =B8 -> 359.26667 | D8: Avis 2026 sur revenus 2025 : 88 664 € soit 7 388,66 €/mois, contre 7 029,40 € retenus par Mme. Mettre 0 pour conserver son chiffre.
A9: Part des frais de garde CESU correspondant au ménage | B9: 0 | C9: =B9*Comparatif!C34 -> 0 | D9: Les conclusions (§13) reconnaissent que les sommes CESU couvrent aussi des prestations de ménage. Saisir la part estimée (ex. 30 %).
A10: Exclure le prêt étudiant HEC (choix personnel) | B10: 1 | C10: =B10*Comparatif!C24 -> 845.68 | D10: 1 = exclu, 0 = conservé. Prêt personnel antérieur, sans lien avec l'entretien de l'enfant.
A11: Exclure le crédit à la consommation (nouveau, objet non précisé) | B11: 1 | C11: =B11*Comparatif!C26 -> 400 | D11: 1 = exclu, 0 = conservé. Apparu entre la requête de juin et les conclusions d'octobre (pièce 70).
A12: Part du crédit immobilier NON retenue comme charge (capitalisation) | B12: 0 | C12: =B12*(Comparatif!C11+Comparatif!C12) -> 0 | D12: Le remboursement d'un emprunt immobilier enrichit le patrimoine de l'emprunteur ; le juge peut le pondérer. 0 % = charge admise en totalité (position de Mme).
A13: Correction de la ligne impôts (écart requête → conclusions) | B13: 0 | C13: =B13 -> 0 | D13: L'impôt passe de 390,75 € à 1 251,33 €/mois entre juin et octobre 2026 sans explication. Saisir ici le montant à neutraliser si l'écart n'est pas justifié par la pièce 68.
A14: DISPONIBLE CORRIGÉ – MME GRAMOND | C14: =B6+SUM(C7:C13) -> 3746.1167
A16: M. DU VIVIER – à partir du projet du 18/09/2026
A17: Disponible calculé (onglet Comparatif, col. E, scolarité incluse) | B17: =Comparatif!E45 -> 3300.0675 | D17: Lien vers l'onglet Comparatif. Inférieur de 305,25 € au chiffre du projet (3 605,32 €) car la scolarité y était omise du total.
A18: Retenir la moyenne 2026 sur 8 mois (lecture adverse) : écart mensuel | B18: =92198.33/8-130116/12 -> 681.79125 | C18: =B18 -> 681.79125 | D18: 92 198,33 € / 8 = 11 524,79 €/mois (conclusions adverses) contre 10 843 € (130 116 / 12). Le projet indiquait 7 683,19 € = 92 198,33 / 12 : division par 12 d'un cumul de 8 mois, à corriger. Mettre 0 pour rester sur le revenu 2025.
A19: Loyer ou crédit immobilier du logement (non déclaré) | B19: 0 | C19: =-B19 -> 0 | D19: Le projet ne liste aucun loyer ni crédit pour le 20 rue de Messine. Saisir le montant réel s'il existe (charge admise au même titre que celle de Mme).
A20: Assurance habitation (laissée en blanc dans le projet) | B20: 0 | C20: =-B20 -> 0 | D20: Montant « .. € » dans le projet. Saisir le montant réel.
A21: Double comptage jeune fille au pair / frais de garde (montant à retirer) | B21: 0 | C21: =B21 -> 0 | D21: Les conclusions adverses soutiennent que 600 € + 621,82 € désignent la même dépense. Si les lignes 649,50 + 232,33 sont déjà comprises dans les 14 923,67 € de la pièce 35, saisir 881,83.
A22: Revenus de Mme DU VIVIER (épouse) à réintégrer dans le foyer | B22: 0 | C22: =B22 -> 0 | D22: Projet : congé parental depuis le 01/10/2025, aucun revenu. Conclusions adverses : 30 099 € en 2025 (2 508 €/mois) et WhatsApp de la nounou du 24/06/2026. Les ressources du conjoint ne sont pas des ressources du débiteur mais réduisent ses charges de foyer.
A23: Frais de garde : part correspondant au ménage ou à l'enfant Charles | B23: 0 | C23: =B23*Comparatif!E34 -> 0 | D23: Symétrique du retraitement appliqué à Mme. Saisir la part des 1 243,64 € qui ne concerne pas Aliénor.
A24: DISPONIBLE CORRIGÉ – M. DU VIVIER | C24: =B17+SUM(C18:C23) -> 3981.8587
A26: SYNTHÈSE
A27: Disponible déclaré par chaque partie (Mme / M.) | B27: =Comparatif!C46 -> -358.83 | C27: =Comparatif!E46 -> 3605.32 | D27: =B27-C27 -> -3964.15
A28: Disponible calculé ligne à ligne (Mme / M.) | B28: =Comparatif!C45 -> -358.83 | C28: =Comparatif!E45 -> 3300.0675 | D28: =B28-C28 -> -3658.8975
A29: Disponible corrigé avec les leviers ci-dessus (Mme / M.) | B29: =C14 -> 3746.1167 | C29: =C24 -> 3981.8587 | D29: =B29-C29 -> -235.74208

Sheet Barème indicatif
A1: Table de référence du ministère de la Justice – ordre de grandeur (1 enfant)
A2: Formule : (revenu net du débiteur – minimum vital) × taux. Taux pour 1 enfant : 9 % en résidence alternée, 13,5 % en résidence classique (DVH 1 week-end sur 2 + moitié des vacances), 18 % en DVH réduit. Le barème n'a qu'une valeur indicative ; il ne déduit aucune charge de logement. Minimum vital = montant forfaitaire du RSA pour une personne seule : valeur à vérifier à la date de l'audience.
A4: Revenu net mensuel du débiteur retenu | B4: =Comparatif!E9 -> 10981.083
A5: Minimum vital (RSA personne seule, à vérifier) | B5: 646.52
A6: Taux – résidence alternée (1 enfant) | B6: 0.09
A7: Taux – résidence classique (1 enfant) | B7: 0.135
A8: Taux – DVH réduit (1 enfant) | B8: 0.18
A10: Pension indicative – résidence alternée (situation actuelle) | B10: =MAX(0,B4-B5)*B6 -> 930.1107
A11: Pension indicative – résidence chez la mère (demande adverse) | B11: =MAX(0,B4-B5)*B7 -> 1395.1661
A12: Pension actuellement versée (indexée, selon le projet) | B12: =Comparatif!E31 -> 2570
A13: Pension demandée par Mme GRAMOND | B13: 3000
A15: Source : table de référence annexée à la circulaire du 12 avril 2010, mise à jour annuelle publiée par le ministère de la Justice. Les taux sont ceux de la table ; le minimum vital est une hypothèse saisie par Claude, à contrôler.
